{% macro acrobot(m1, m2, l1, l2, I1, I2, b1, b2, cf1, cf2) %}
<robot name="acrobot">

  <joint name="base_weld" type="fixed">
      <parent link="world"/>
      <child link="base_link"/>
  </joint>  

  <link
    name="base_link">
    <inertial>
      <origin
        xyz="-0.025147 -2.3875E-12 -0.021712"
        rpy="0 0 0" />
      <mass
        value="1.0806" />
      <inertia
        ixx="0.0052004"
        ixy="-2.3051E-14"
        ixz="-0.00037275"
        iyy="0.001836"
        iyz="-3.2374E-14"
        izz="0.0051241" />
    </inertial>
    <visual>
      <origin
        xyz="0 0 0"
        rpy="0 0 0" />
      <geometry>
        <mesh
          filename="./meshes/base_link.obj" />
      </geometry>
      <material
        name="">
        <color
          rgba="0.89804 0.91765 0.92941 1" />
      </material>
    </visual>   
  </link>

  <link
    name="Link1">
    <inertial>
      <origin
        xyz="0 0 -0.27401315789473685"
        rpy="0 0 0" />
      <mass
        value="{{ m1 }}" /> 
      <inertia
        ixx="{{ I1 }}"
        ixy="0.0"
        ixz="0.0"
        iyy="{{ I1 }}"
        iyz="0.0"
        izz="{{ I1 }}" />
    </inertial>
    <visual>
      <origin
        xyz="0 0 0"
        rpy="0 0 0" />
      <geometry>
        <mesh
          filename="./meshes/Link1.obj" />
      </geometry>
      <material
        name="">
        <color
          rgba="0.75294 0.75294 0.75294 1" />
      </material>
    </visual>  
  </link>

  <joint
    name="Joint1"
    type="revolute">
    <origin
      xyz="0.0342 0 0"
      rpy="0 0 0" />
    <parent
      link="base_link" />
    <child
      link="Link1" />
    <axis
      xyz="1 0 0" />
    <limit
      lower="-3.1415926"
      upper="3.1415926"
      effort="16"
      velocity="20" />
    <dynamics 
        damping="{{ b1 }}" 
        friction="{{ cf1 }}"/>
  </joint>

  <link
    name="Link2">
    <inertial>
      <origin
        xyz="0 0 0.16634950840469392"
        rpy="0 0 0" />
      <mass
        value="{{ m2 }}" />
      <inertia
        ixx="{{ I2 }}"
        ixy="0.0"
        ixz="0.0"
        iyy="{{ I2 }}"
        iyz="0.0"
        izz="{{ I2 }}" />
    </inertial>
    <visual>
      <origin
        xyz="0 0 0"
        rpy="0 0 0" />
      <geometry>
        <mesh
          filename="./meshes/Link2.obj" />
      </geometry>
      <material
        name="">
        <color
          rgba="0.75294 0.75294 0.75294 1" />
      </material>
    </visual>  
  </link>
  
  <joint
    name="Joint2"
    type="revolute">
    <origin
      xyz="0.0522 0 -0.3"
      rpy="-3.1416 0 0" />
    <parent
      link="Link1" />
    <child
      link="Link2" />
    <axis
      xyz="1 0 0" />
    <limit
      lower="-3.1415926"
      upper="3.1415926"
      effort="16"
      velocity="20" />
    <dynamics 
        damping="{{ b2 }}" 
        friction="{{ cf2 }}"/>
  </joint>

  <link
    name="Weight">
    <inertial>
      <origin
        xyz="0.010583 -7.0876E-12 -1.5468E-12"
        rpy="0 0 0" />
      <mass
        value="0" />
      <inertia
        ixx="0.0"
        ixy="0.0"
        ixz="0.0"
        iyy="0.0"
        iyz="0.0"
        izz="0.0" />
    </inertial>
    <visual>
      <origin
        xyz="0 0 0"
        rpy="0 0 0" />
      <geometry>
        <mesh
          filename="./meshes/Weight.obj" />
      </geometry>
      <material
        name="">
        <color
          rgba="0.69804 0.69804 0.69804 1" />
      </material>
    </visual>  
  </link>
  
  <joint
    name="Weight"
    type="fixed">
    <origin
      xyz="0.0 0 0.0"
      rpy="0 0 0" />
    <parent
      link="Link2" />
    <child
      link="Weight" />
    <axis
      xyz="0 0 0" />
  </joint>
  
  <transmission type="SimpleTransmission" name="elbow_trans">
    <actuator name="Joint2"/>
    <joint name="Joint2"/>
    <mechanicalReduction>1</mechanicalReduction>
  </transmission>

</robot>
{%- endmacro %}